<?xml version="1.0"?>
<!--
  Gazebo ROS FT Sensor plugin demo

  Listen to the published wrench messages:

  ros2 topic echo /demo_link/ft_sensor_demo
  ros2 topic echo /demo_joint/ft_sensor_demo
-->
<sdf version="1.6">
  <world name="default">

    <physics type="ode">
      <ode>
        <ode_quiet>1</ode_quiet>
        <solver>
          <type>world</type>
        </solver>
      </ode>
    </physics>

    <include>
      <uri>model://ground_plane</uri>
    </include>

    <include>
      <uri>model://sun</uri>
    </include>

    <model name="double_pendulum_with_base">
      <link name="base">
        <inertial>
          <mass>100</mass>
        </inertial>
        <visual name="vis_plate_on_ground">
          <pose>0 0 0.01 0 0 0</pose>
          <geometry>
            <cylinder>
              <radius>0.8</radius>
              <length>0.02</length>
            </cylinder>
          </geometry>
        </visual>
        <visual name="vis_pole">
          <pose>-0.275 0 1.1 0 0 0</pose>
          <geometry>
            <box>
              <size>0.2 0.2 2.2</size>
            </box>
          </geometry>
        </visual>
        <collision name="col_plate_on_ground">
          <pose>0 0 0.01 0 0 0</pose>
          <geometry>
            <cylinder>
              <radius>0.8</radius>
              <length>0.02</length>
            </cylinder>
          </geometry>
        </collision>
        <collision name="col_pole">
          <pose>-0.275 0 1.1 0 0 0</pose>
          <geometry>
            <box>
              <size>0.2 0.2 2.2</size>
            </box>
          </geometry>
        </collision>
      </link>
      <!-- upper link, length 1, IC -90 degrees -->
      <link name="upper_link">
        <pose>0 0 2.1 -1.5708 0 0</pose>
        <self_collide>0</self_collide>
        <inertial>
          <pose>0 0 0.5 0 0 0</pose>
        </inertial>
        <visual name="vis_upper_joint">
          <pose>-0.05 0 0 0 1.5708 0</pose>
          <geometry>
            <cylinder>
              <radius>0.1</radius>
              <length>0.3</length>
            </cylinder>
          </geometry>
        </visual>
        <visual name="vis_lower_joint">
          <pose>0 0 1.0 0 1.5708 0</pose>
          <geometry>
            <cylinder>
              <radius>0.1</radius>
              <length>0.2</length>
            </cylinder>
          </geometry>
        </visual>
        <visual name="vis_cylinder">
          <pose>0 0 0.5 0 0 0</pose>
          <geometry>
            <cylinder>
              <radius>0.1</radius>
              <length>0.9</length>
            </cylinder>
          </geometry>
        </visual>
        <collision name="col_upper_joint">
          <pose>-0.05 0 0 0 1.5708 0</pose>
          <geometry>
            <cylinder>
              <radius>0.1</radius>
              <length>0.3</length>
            </cylinder>
          </geometry>
        </collision>
        <collision name="col_lower_joint">
          <pose>0 0 1.0 0 1.5708 0</pose>
          <geometry>
            <cylinder>
              <radius>0.1</radius>
              <length>0.2</length>
            </cylinder>
          </geometry>
        </collision>
        <collision name="col_cylinder">
          <pose>0 0 0.5 0 0 0</pose>
          <geometry>
            <cylinder>
              <radius>0.1</radius>
              <length>0.9</length>
            </cylinder>
          </geometry>
        </collision>
      </link>
      <!-- lower link, length 1, IC ~-120 degrees more -->
      <link name="lower_link">
        <pose>0.25 1.0 2.1 -2 0 0</pose>
        <self_collide>0</self_collide>
        <inertial>
          <pose>0 0 0.5 0 0 0</pose>
        </inertial>
        <visual name="vis_lower_joint">
          <pose>0 0 0 0 1.5708 0</pose>
          <geometry>
            <cylinder>
              <radius>0.08</radius>
              <length>0.3</length>
            </cylinder>
          </geometry>
        </visual>
        <visual name="vis_cylinder">
          <pose>0 0 0.5 0 0 0</pose>
          <geometry>
            <cylinder>
              <radius>0.1</radius>
              <length>0.9</length>
            </cylinder>
          </geometry>
        </visual>
        <collision name="col_lower_joint">
          <pose>0 0 0 0 1.5708 0</pose>
          <geometry>
            <cylinder>
              <radius>0.08</radius>
              <length>0.3</length>
            </cylinder>
          </geometry>
        </collision>
        <collision name="col_cylinder">
          <pose>0 0 0.5 0 0 0</pose>
          <geometry>
            <cylinder>
              <radius>0.1</radius>
              <length>0.9</length>
            </cylinder>
          </geometry>
        </collision>
      </link>
      <!-- pin joint for upper link, at origin of upper link -->
      <joint name="upper_joint" type="revolute">
        <parent>base</parent>
        <child>upper_link</child>
        <axis>
          <xyz>1.0 0 0</xyz>
        </axis>
      </joint>
      <!-- pin joint for lower link, at origin of child link -->
      <joint name="lower_joint" type="revolute">
        <parent>upper_link</parent>
        <child>lower_link</child>
        <axis>
          <xyz>1.0 0 0</xyz>
        </axis>
        <physics>
          <provide_feedback>true</provide_feedback>
        </physics>
      </joint>

      <plugin name="gazebo_ros_ft_sensor_joint" filename="libgazebo_ros_ft_sensor.so">
        <ros>
          <namespace>/demo_joint</namespace>
          <remapping>wrench:=ft_sensor_demo</remapping>
        </ros>
        <update_rate>200</update_rate>
        <joint_name>lower_joint</joint_name>
        <gaussian_noise>0.01</gaussian_noise>
      </plugin>

      <plugin name="gazebo_ros_ft_sensor_link" filename="libgazebo_ros_ft_sensor.so">
        <ros>
          <namespace>/demo_link</namespace>
          <remapping>wrench:=ft_sensor_demo</remapping>
        </ros>
        <update_rate>200</update_rate>
        <body_name>upper_link</body_name>
        <frame_name>world_demo</frame_name>
        <gaussian_noise>0.01</gaussian_noise>
      </plugin>

    </model>
  </world>
</sdf>
