<?xml version="1.0"?>
<!--
  Gazebo ROS differential drive plugin demo

  Try sending commands:

    ros2 topic pub /demo/cmd_demo geometry_msgs/Twist '{linear: {x: 1.0}}' -1

    ros2 topic pub /demo/cmd_demo geometry_msgs/Twist '{angular: {z: 0.1}}' -1

  Try listening to odometry:

    ros2 topic echo /demo/odom_demo

  Try listening to TF:

    ros2 run tf2_ros tf2_echo odom_demo chassis

    ros2 run tf2_ros tf2_echo chassis right_wheel

    ros2 run tf2_ros tf2_echo chassis left_wheel
-->
<sdf version="1.6">
  <world name="default">

    <include>
      <uri>model://ground_plane</uri>
    </include>

    <include>
      <uri>model://sun</uri>
    </include>

    <model name='vehicle'>
      <pose>0 0 0 0 -0 0</pose>

      <link name='chassis'>
        <pose>0 -0 0.175 0 -0 0</pose>
        <inertial>
          <mass>1.14395</mass>
          <inertia>
            <ixx>0.126164</ixx>
            <ixy>0</ixy>
            <ixz>0</ixz>
            <iyy>0.416519</iyy>
            <iyz>0</iyz>
            <izz>0.481014</izz>
          </inertia>
        </inertial>
        <visual name='visual'>
          <geometry>
            <cylinder>
              <length>0.15</length>
              <radius>0.13</radius>
            </cylinder>
          </geometry>
        </visual>
        <collision name='collision'>
          <geometry>
            <cylinder>
              <length>0.15</length>
              <radius>0.13</radius>
            </cylinder>
          </geometry>
        </collision>
      </link>

      <link name='left_wheel'>
        <pose frame=''>0.09 0.155885 0.05 0 -0 1.0472</pose>
        <inertial>
          <pose frame=''>0 0 0 0 -0 0</pose>
          <mass>0.4</mass>
          <inertia>
            <ixx>0.0124118</ixx>
            <ixy>-0.000711734</ixy>
            <ixz>0.00050273</ixz>
            <iyy>0.0152182</iyy>
            <iyz>-4.27347e-06</iyz>
            <izz>0.011764</izz>
          </inertia>
        </inertial>
        <collision name='wheel_link_left_collision'>
          <pose frame=''>0 0 0 3.14159 1.57079 3.14159</pose>
          <geometry>
            <cylinder>
              <length>0.025</length>
              <radius>0.05</radius>
            </cylinder>
          </geometry>
          <surface>
            <contact>
              <ode>
                <kp>1e+07</kp>
                <kd>1</kd>
              </ode>
            </contact>
            <friction>
              <ode>
                <mu>1</mu>
                <mu2>0</mu2>
                <fdir1>0 1 0</fdir1>
              </ode>
            </friction>
          </surface>
        </collision>
        <visual name='wheel_link_left_visual'>
          <pose frame=''>0 0 0 3.14159 1.57079 3.14159</pose>
          <geometry>
            <cylinder>
              <length>0.025</length>
              <radius>0.05</radius>
            </cylinder>
          </geometry>
          <material>
            <script>
              <uri>__default__</uri>
              <name>__default__</name>
            </script>
          </material>
        </visual>
        <gravity>1</gravity>
        <velocity_decay/>
      </link>

      <link name='back_wheel'>
        <pose frame=''>-0.18 0 0.05 0 -0 3.14159</pose>
        <inertial>
          <pose frame=''>0 0 0 0 -0 0</pose>
          <mass>0.4</mass>
          <inertia>
            <ixx>0.0124118</ixx>
            <ixy>-0.000711734</ixy>
            <ixz>0.00050273</ixz>
            <iyy>0.0152182</iyy>
            <iyz>-4.27347e-06</iyz>
            <izz>0.011764</izz>
          </inertia>
        </inertial>
        <collision name='wheel_link_back_collision'>
          <pose frame=''>0 0 0 3.14159 1.57079 3.14159</pose>
          <geometry>
            <cylinder>
              <length>0.025</length>
              <radius>0.05</radius>
            </cylinder>
          </geometry>
          <surface>
            <contact>
              <ode>
                <kp>1e+07</kp>
                <kd>1</kd>
              </ode>
            </contact>
            <friction>
              <ode>
                <mu>1</mu>
                <mu2>0</mu2>
                <fdir1>0 1 0</fdir1>
              </ode>
            </friction>
          </surface>
        </collision>
        <visual name='wheel_link_back_visual'>
          <pose frame=''>0 0 0 3.14159 1.57079 3.14159</pose>
          <geometry>
            <cylinder>
              <length>0.025</length>
              <radius>0.05</radius>
            </cylinder>
          </geometry>
          <material>
            <script>
              <uri>__default__</uri>
              <name>__default__</name>
            </script>
          </material>
        </visual>
        <gravity>1</gravity>
        <velocity_decay/>
      </link>

      <link name='right_wheel'>
        <pose frame=''>0.09 -0.155885 0.05 0 -0 -1.0472</pose>
        <inertial>
          <pose frame=''>0 0 0 0 -0 0</pose>
          <mass>0.4</mass>
          <inertia>
            <ixx>0.0124118</ixx>
            <ixy>-0.000711734</ixy>
            <ixz>0.00050273</ixz>
            <iyy>0.0152182</iyy>
            <iyz>-4.27347e-06</iyz>
            <izz>0.011764</izz>
          </inertia>
        </inertial>
        <collision name='wheel_link_right_collision'>
          <pose frame=''>0 0 0 3.14159 1.57079 3.14159</pose>
          <geometry>
            <cylinder>
              <length>0.025</length>
              <radius>0.05</radius>
            </cylinder>
          </geometry>
          <surface>
            <contact>
              <ode>
                <kp>1e+07</kp>
                <kd>1</kd>
              </ode>
            </contact>
            <friction>
              <ode>
                <mu>1</mu>
                <mu2>0</mu2>
                <fdir1>0 1 0</fdir1>
              </ode>
            </friction>
          </surface>
        </collision>
        <visual name='wheel_link_right_visual'>
          <pose frame=''>0 0 0 3.14159 1.57079 3.14159</pose>
          <geometry>
            <cylinder>
              <length>0.025</length>
              <radius>0.05</radius>
            </cylinder>
          </geometry>
          <material>
            <script>
              <uri>__default__</uri>
              <name>__default__</name>
            </script>
          </material>
        </visual>
        <gravity>1</gravity>
        <velocity_decay/>
      </link>

      <joint name='left_wheel_joint' type='revolute'>
        <parent>chassis</parent>
        <child>left_wheel</child>
        <axis>
          <xyz>0.5 0.866025 0</xyz>
          <limit>
            <lower>-1e+16</lower>
            <upper>1e+16</upper>
          </limit>
          <dynamics>
            <spring_reference>0</spring_reference>
            <spring_stiffness>0</spring_stiffness>
          </dynamics>
          <use_parent_model_frame>1</use_parent_model_frame>
        </axis>
      </joint>

      <joint name='right_wheel_joint' type='revolute'>
        <parent>chassis</parent>
        <child>right_wheel</child>
        <axis>
          <xyz>0.5 -0.866025 0</xyz>
          <limit>
            <lower>-1e+16</lower>
            <upper>1e+16</upper>
          </limit>
          <dynamics>
            <spring_reference>0</spring_reference>
            <spring_stiffness>0</spring_stiffness>
          </dynamics>
          <use_parent_model_frame>1</use_parent_model_frame>
        </axis>
      </joint>

      <joint name='back_wheel_joint' type='revolute'>
        <parent>chassis</parent>
        <child>back_wheel</child>
        <axis>
          <xyz>-1 0 0</xyz>
          <limit>
            <lower>-1e+16</lower>
            <upper>1e+16</upper>
          </limit>
          <dynamics>
            <spring_reference>0</spring_reference>
            <spring_stiffness>0</spring_stiffness>
          </dynamics>
          <use_parent_model_frame>1</use_parent_model_frame>
        </axis>
      </joint>

      <plugin name='omni_3wd_drive' filename='libgazebo_ros_omni_3wd_drive.so'>

        <ros>
          <namespace>/</namespace>
          <remapping>cmd_vel:=cmd_demo</remapping>
          <remapping>odom:=odom_demo</remapping>
        </ros>

        <!-- wheels -->
        <left_joint>left_wheel_joint</left_joint>
        <right_joint>right_wheel_joint</right_joint>
        <back_joint>back_wheel_joint</back_joint>

        <!-- kinematics -->
        <wheel_separation>0.18</wheel_separation>
        <wheel_diameter>0.1</wheel_diameter>

        <!-- limits -->
        <max_wheel_torque>20</max_wheel_torque>
        <max_wheel_acceleration>1.0</max_wheel_acceleration>

        <!-- output -->
        <publish_odom>true</publish_odom>
        <publish_odom_tf>true</publish_odom_tf>
        <publish_wheel_tf>true</publish_wheel_tf>

        <odometry_frame>odom_demo</odometry_frame>
        <robot_base_frame>chassis</robot_base_frame>

      </plugin>

    </model>

  </world>
</sdf>
